<?xml version="1.0"?>
<robot xmlns:xacro="http://www.ros.org/wiki/xacro">

    <xacro:include filename="inertia.marcos.xacro"/>

    <material name= "white">
        <color rgba= "1 1 1 1"/>
    </material>

    <material name= "blue">
        <color rgba= "0.2 0.2 1 1"/>
    </material>

    <material name= "orange">
        <color rgba= "1 0.3 0.1 1"/>
    </material>

    <material name= "black">
        <color rgba= "0 0 0 1"/>
    </material>

    <material name= "red">
        <color rgba= "1 0 0 1"/>
    </material>

    <!--base link-->
    <link name="base_link">

    </link>
    
    <!-- foot print joint-->

    <joint name="base_footprint_joint" type="fixed">
        <parent link="base_link"/>
        <child link="base_footprint"/>
        <origin xyz="0 0 0" rpy="0 0 0"/>
    </joint>

    <link name="base_footprint">
    </link>
    
    <!-- cHASIS JOINT-->
    <joint name="chassis_joint" type="fixed">
        <parent link="base_link"/>
        <child link="chassis"/>
        <origin xyz="-0.1 0 0"/>
    </joint>

    <!--chassis link-->
    <link name="chassis">
        <visual>
            <origin xyz="0.25 0 0.05"/>
            <geometry>
                <box size="0.5 0.3 0.10"/>
            </geometry>
            <material name="white"/>
        </visual>
        <collision>
            <origin xyz="0.25 0 0.05"/>
            <geometry>
                <box size="0.5 0.3 0.10"/>
            </geometry>
        </collision>
        <xacro:inertial_box mass="0.5" x="0.5" y="0.3" z="0.10">
            <origin xyz="0.25 0 0.05" rpy="0 0 0"/>
        </xacro:inertial_box>
    </link>
    
    <gazebo reference="chassis">
        <material>Gazebo/White</material>
    </gazebo>
    
    <!--left down wheel joint-->
    <joint name="left_down_wheel_joint" type="continuous">
        <parent link="base_link"/>
        <child link="left_down_wheel_link"/>
        <origin xyz="0 0.175 0" rpy="-${pi/2} 0 0"/>
        <axis xyz="0 0 1"/>
    </joint>

    <!--left down wheel link-->
    <link name="left_down_wheel_link">
        <visual>
            <origin xyz="0 0 0"/>
            <geometry>
                <cylinder radius="0.05" length="0.04"/>
            </geometry>
            <material name="blue"/> 
        </visual>
        <collision>
            <origin xyz="0 0 0"/>
            <geometry>
                <cylinder radius="0.05" length="0.04"/>
            </geometry>
        </collision>
        <xacro:inertial_cylinder mass="0.1" radius="0.05" length="0.04">
            <origin xyz="0 0 0" rpy="0 0 0"/>
        </xacro:inertial_cylinder>
    </link>
    

    <gazebo reference="left_down_wheel_link">
        <material>Gazebo/Blue</material>
    </gazebo>
    
    <!--right down wheel joint-->
    <joint name="right_down_wheel_joint" type="continuous">
        <parent link="base_link"/>
        <child link="right_down_wheel_link"/>
        <origin xyz="0 -0.175 0" rpy="${pi/2} 0 0"/>
        <axis xyz="0 0 -1"/>
    </joint>

    <!--right down wheel link-->
    <link name="right_down_wheel_link">
        <visual>
            <origin xyz="0 0 0"/>
            <geometry>
                <cylinder radius="0.05" length="0.04"/>
            </geometry>
            <material name="blue"/> 
        </visual>
        <collision>
            <origin xyz="0 0 0"/>
            <geometry>
                <cylinder radius="0.05" length="0.04"/>
            </geometry>
        </collision>
        <xacro:inertial_cylinder mass="0.1" radius="0.05" length="0.04">
            <origin xyz="0 0 0" rpy="0 0 0"/>
        </xacro:inertial_cylinder>
    </link>

    <gazebo reference="right_down_wheel_link">
        <material>Gazebo/Blue</material>
    </gazebo>

    <!--left up wheel joint-->
    <joint name="left_up_wheel_joint" type="continuous">
        <parent link="base_link"/>
        <child link="left_up_wheel_link"/>
        <origin xyz="0.3 0.175 0" rpy="-${pi/2} 0 0"/>
        <axis xyz="0 0 1"/>
    </joint>

    <!--left up wheel link-->
    <link name="left_up_wheel_link">
        <visual>
            <origin xyz="0 0 0"/>
            <geometry>
                <cylinder radius="0.05" length="0.04"/>
            </geometry>
            <material name="blue"/> 
        </visual>
        <collision>
            <origin xyz="0 0 0"/>
            <geometry>
                <cylinder radius="0.05" length="0.04"/>
            </geometry>
        </collision>
        <xacro:inertial_cylinder mass="0.1" radius="0.05" length="0.04">
            <origin xyz="0 0 0" rpy="0 0 0"/>
        </xacro:inertial_cylinder>
    </link>

    <gazebo reference="left_up_wheel_link">
        <material>Gazebo/Blue</material>
    </gazebo>

    <!--right up wheel joint-->
    <joint name="right_up_wheel_joint" type="continuous">
        <parent link="base_link"/>
        <child link="right_up_wheel_link"/>
        <origin xyz="0.3 -0.175 0" rpy="${pi/2} 0 0"/>
        <axis xyz="0 0 -1"/>
    </joint>

    <!--right up wheel link-->
    <link name="right_up_wheel_link">
        <visual>
            <origin xyz="0 0 0"/>
            <geometry>
                <cylinder radius="0.05" length="0.04"/>
            </geometry>
            <material name="blue"/> 
        </visual>
        <collision>
            <origin xyz="0 0 0"/>
            <geometry>
                <cylinder radius="0.05" length="0.04"/>
            </geometry>
        </collision>
        <xacro:inertial_cylinder mass="0.1" radius="0.05" length="0.04">
            <origin xyz="0 0 0" rpy="0 0 0"/>
        </xacro:inertial_cylinder>
    </link>

    <gazebo reference="right_up_wheel_link">
        <material>Gazebo/Blue</material>
    </gazebo>
    

</robot>